Workbook

Sheet Sheet1
B1: MEAN TRAVEL TIME FOR WASHCOG REGION
C2: AM AND PM PEAK PERIOD
B4: Home to Work | C4: Work to Home | D4: Home to Other | E4: Other to Home | F4: Work to Other | G4: Other to Work | H4: Other to Other
A5: Drive Alone 1968 | B5: 28.3 | C5: 32.5 | D5: 19.2 | E5: 17.8 | F5: 27.3 | G5: 24.4 | H5: 17.9
A6: Drive Alone 1988 | B6: 28.9 | C6: 32.5 | D6: 18.6 | E6: 19.9 | F6: 26.6 | G6: 25.8 | H6: 17.8
A7: Carpool 2 1968 | B7: 32.3 | C7: 36.4 | D7: 17.2 | E7: 17.9 | F7: 27.8 | G7: 25.8 | H7: 17.1
A8: Carpool 2 1988 | B8: 31.2 | C8: 32.3 | D8: 18.1 | E8: 18.7 | F8: 26.4 | G8: 32.9 | H8: 17
A9: Carpool 3+ 1968 | B9: 40.7 | C9: 47.3 | D9: 17.3 | E9: 18.5 | F9: 32.3 | G9: 35 | H9: 15.1
A10: Carpool 3+ 1988 | B10: 37.8 | C10: 44.1 | D10: 16.7 | E10: 15.1 | F10: 30.1 | G10: 33.5 | H10: 18.2
A11: Walk to Transit 1968 | B11: 44.3 | C11: 51.4 | D11: 39.6 | E11: 42.8 | F11: 38.5 | G11: 36.8 | H11: 33.5
A12: Walk to Transit 1988 | B12: 39.6 | C12: 43.8 | D12: 36 | E12: 36.3 | F12: 37.6 | G12: 23.9 | H12: 34.6
A13: Park and Ride 1988 | B13: 55.5 | C13: 53.1 | D13: 36 | G13: 43.7
A14: Kiss and Ride 1988 | B14: 49.3 | C14: 57.4
A15: Walk 1988 | B15: 20.3 | C15: 19.9 | D15: 13.6 | E15: 14 | F15: 16.8 | G15: 14.5 | H15: 18.6
B18: Work Trips | C18: Home-Based Nonwork | D18: Work-Based Nonwork | E18: Other-Based Other
A19: Drive Alone 1968 | B19: =(B5+C5)/2 -> 30.4 | C19: =(D5+E5)/2 -> 18.5 | D19: =(F5+G5)/2 -> 25.85 | E19: =H5 -> 17.9
A20: Drive Alone 1988 | B20: =(B6+C6)/2 -> 30.7 | C20: =(D6+E6)/2 -> 19.25 | D20: =(F6+G6)/2 -> 26.2 | E20: =H6 -> 17.8
A21: Carpool 2 1968 | B21: =(B7+C7)/2 -> 34.35 | C21: =(D7+E7)/2 -> 17.55 | D21: =(F7+G7)/2 -> 26.8 | E21: =H7 -> 17.1
A22: Carpool 2 1988 | B22: =(B8+C8)/2 -> 31.75 | C22: =(D8+E8)/2 -> 18.4 | D22: =(F8+G8)/2 -> 29.65 | E22: =H8 -> 17
A23: Carpool 3+ 1968 | B23: =(B9+C9)/2 -> 44 | C23: =(D9+E9)/2 -> 17.9 | D23: =(F9+G9)/2 -> 33.65 | E23: =H9 -> 15.1
A24: Carpool 3+ 1988 | B24: =(B10+C10)/2 -> 40.95 | C24: =(D10+E10)/2 -> 15.9 | D24: =(F10+G10)/2 -> 31.8 | E24: =H10 -> 18.2
A25: Walk to Transit 1968 | B25: =(B11+C11)/2 -> 47.85 | C25: =(D11+E11)/2 -> 41.2 | D25: =(F11+G11)/2 -> 37.65 | E25: =H11 -> 33.5
A26: Walk to Transit 1988 | B26: =(B12+C12)/2 -> 41.7 | C26: =(D12+E12)/2 -> 36.15 | D26: =(F12+G12)/2 -> 30.75 | E26: =H12 -> 34.6
A27: Park and Ride 1988 | B27: =(B13+C13)/2 -> 54.3
A28: Kiss and Ride 1988 | B28: =(B14+C14)/2 -> 53.35
A29: Walk 1988 | B29: =(B15+C15)/2 -> 20.1 | C29: =(D15+E15)/2 -> 13.8 | D29: =(F15+G15)/2 -> 15.65 | E29: =H15 -> 18.6
A30: All Modes 1968 | B30: =(32.1+36.9)/2 -> 34.5 | C30: =(19.3+19)/2 -> 19.15 | D30: =(28.7+26.2)/2 -> 27.45 | E30: =17.6 -> 17.6
A31: All Modes 1988 | B31: =(32.2+36.1)/2 -> 34.15 | C31: =(19+20.2)/2 -> 19.6 | D31: =(28.1+27.3)/2 -> 27.7 | E31: =18.5 -> 18.5

Sheet A
I1: 5/26/92
C3: Table 1: | D3: MEAN, MEDIAN, AND SAMPLE SIZE--TRAVEL TIME FOR WASHCOG REGION
E4: AM AND PM PEAK PERIOD
D6: H2W | E6: W2H | F6: H2O | G6: O2H | H6: W2O | I6: O2W | J6: O2O
B8: AUTO1 | C8: 1968 | D8: 28.3 | E8: 32.5 | F8: 19.2 | G8: 17.8 | H8: 27.3 | I8: 24.4 | J8: 17.9
D9: (30.0) | E9: (30.0) | F9: (15.0) | G9: (15.0) | H9: (25.0) | I9: (20.0) | J9: (15.0)
D10: 11633 | E10: 9124 | F10: 3823 | G10: 3656 | H10: 996 | I10: 341 | J10: 738
C11: 1988 | D11: 28.9 | E11: 32.5 | F11: 18.6 | G11: 19.9 | H11: 26.6 | I11: 25.8 | J11: 17.8
D12: (27.5) | E12: (30.0) | F12: (15.0) | G12: (15.0) | H12: (20.0) | I12: (22.0) | J12: (15.0)
D13: 3260 | E13: 2181 | F13: 1378 | G13: 1456 | H13: 847 | I13: 734 | J13: 726
B15: AUTO2 | C15: 1968 | D15: 32.3 | E15: 36.4 | F15: 17.2 | G15: 17.9 | H15: 27.8 | I15: 25.8 | J15: 17.1
D16: (30.0) | E16: (30.0) | F16: (15.0) | G16: (15.0) | H16: (25.0) | I16: (24.0) | J16: (15.0)
D17: 4962 | E17: 3792 | F17: 7068 | G17: 4191 | H17: 399 | I17: 178 | J17: 1337
C18: 1988 | D18: 31.2 | E18: 32.3 | F18: 18.1 | G18: 18.7 | H18: 26.4 | I18: 32.9 | J18: 17
D19: (30.0) | E19: (30.0) | F19: (15.0) | G19: (15.0) | H19: (20.0) | I19: (30.0) | J19: (15.0)
D20: 311 | E20: 196 | F20: 1025 | G20: 651 | H20: 180 | I20: 148 | J20: 530
B22: AUTO3 | C22: 1968 | D22: 40.7 | E22: 47.3 | F22: 17.3 | G22: 18.5 | H22: 32.3 | I22: 35 | J22: 15.1
D23: (40.0) | E23: (45.0) | F23: (10.0) | G23: (15.0) | H23: (30.0) | I23: (25.0) | J23: (10.0)
D24: 403 | E24: 324 | F24: 1194 | G24: 745 | H24: 33 | I24: 27 | J24: 256
C25: 1988 | D25: 37.8 | E25: 44.1 | F25: 16.7 | G25: 15.1 | H25: 30.1 | I25: 33.5 | J25: 18.2
D26: (35.0) | E26: (45.0) | F26: (15.0) | G26: (15.0) | H26: (25.0) | I26: (30.0) | J26: (15.0)
D27: 105 | E27: 70 | F27: 601 | G27: 298 | H27: 57 | I27: 50 | J27: 233
B29: WCT | C29: 1968 | D29: 44.3 | E29: 51.4 | F29: 39.6 | G29: 42.8 | H29: 38.5 | I29: 36.8 | J29: 33.5
D30: (42.5) | E30: (45.0) | F30: (35.0) | G30: (35.0) | H30: (30.0) | I30: (30.0) | J30: (30.0)
D31: 3176 | E31: 2693 | F31: 875 | G31: 391 | H31: 172 | I31: 44 | J31: 72
C32: 1988 | D32: 39.6 | E32: 43.8 | F32: 36 | G32: 36.3 | H32: 37.6 | I32: 23.9 | J32: 34.6
D33: (35.0) | E33: (42.5) | F33: (30.0) | G33: (30.0) | H33: (30.0) | I33: (26.0) | J33: (30.0)
D34: 761 | E34: 637 | F34: 167 | G34: 176 | H34: 159 | I34: 104 | J34: 80
B36: ADT | C36: 1968
C39: 1988 | D39: 55.5 | E39: 53.1 | F39: 36 | I39: 43.7
D40: (55.0) | E40: (60.0) | F40: (35.0) | I40: (40.0)
D41: 146 | E41: 91 | F41: 4 | G41: 2 | I41: 21 | J41: 4
B43: APT | C43: 1968
C46: 1988 | D46: 49.3 | E46: 57.4
D47: (47.5) | E47: (60.0)
D48: 84 | E48: 72 | F48: 3 | G48: 4 | I48: 7 | J48: 3
B50: WALK | C50: 1968 | D50: 14.4
D51: (10.0)
D52: 773 | E52: 1
C53: 1988 | D53: 20.3 | E53: 19.9 | F53: 13.6 | G53: 14 | H53: 16.8 | I53: 14.5 | J53: 18.6
...

Sheet B
A1: Table 1: Change in Person Work Trip Volume Between 1968 and 1988:
E5: D E S T I N A T I O N
A7: ORIGIN | B7: CENTER CITY | E7: INNER SUBURBS | H7: OUTER SUBURBS | K7: TOTAL
D8: % | G8: % | J8: % | M8: %
B9: 1968 | C9: 1988 | D9: Change | E9: 1968 | F9: 1988 | G9: Change | H9: 1968 | I9: 1988 | J9: Change | K9: 1968 | L9: 1988 | M9: Change
A12: CENTER CITY | B12: 235.4 | C12: 251.6 | D12: =((C12-B12)/B12)*100 -> 6.8819031 | E12: 32 | F12: 31.1 | G12: =((F12-E12)/E12)*100 -> -2.8125 | H12: 14.4 | I12: 25.4 | J12: =((I12-H12)/H12)*100 -> 76.388889 | K12: =B12+E12+H12 -> 281.8 | L12: =C12+F12+I12 -> 308.1 | M12: =((L12-K12)/K12)*100 -> 9.3328602
A14: INNER SUBURBS | B14: 122.1 | C14: 125.7 | D14: =((C14-B14)/B14)*100 -> 2.9484029 | E14: 58.3 | F14: 91 | G14: =((F14-E14)/E14)*100 -> 56.089194 | H14: 29.7 | I14: 57.4 | J14: =((I14-H14)/H14)*100 -> 93.265993 | K14: =B14+E14+H14 -> 210.1 | L14: =C14+F14+I14 -> 274.1 | M14: =((L14-K14)/K14)*100 -> 30.461685
A16: OUTER SUBURBS | B16: 85.9 | C16: 192.1 | D16: =((C16-B16)/B16)*100 -> 123.63213 | E16: 40.9 | F16: 106.4 | G16: =((F16-E16)/E16)*100 -> 160.1467 | H16: 73.6 | I16: 342.1 | J16: =((I16-H16)/H16)*100 -> 364.80978 | K16: =B16+E16+H16 -> 200.4 | L16: =C16+F16+I16 -> 640.6 | M16: =((L16-K16)/K16)*100 -> 219.66068
A19: TOTAL | B19: =SUM(B12:B17) -> 443.4 | C19: =SUM(C12:C17) -> 569.4 | D19: =((C19-B19)/B19)*100 -> 28.416779 | E19: =SUM(E12:E17) -> 131.2 | F19: =SUM(F12:F17) -> 228.5 | G19: =((F19-E19)/E19)*100 -> 74.161585 | H19: =SUM(H12:H17) -> 117.7 | I19: =SUM(I12:I17) -> 424.9 | J19: =((I19-H19)/H19)*100 -> 261.00255 | K19: =SUM(K12:K17) -> 692.3 | L19: =SUM(L12:L17) -> 1222.8 | M19: =((L19-K19)/K19)*100 -> 76.628629
A22: Source: 1968 and 1987/88 Metropolitan Washington Council of Governments Household Travel Surveys
A23: Note: A.M. Peak: 6-9 AM

Sheet C
A1: Table 2: Change in Average Work Trip Time Between 1968 and 1988:
E5: D E S T I N A T I O N
A7: ORIGIN | B7: CENTER CITY | E7: INNER SUBURBS | H7: OUTER SUBURBS | K7: REGIONAL AVERAGE
D8: % | G8: % | J8: % | M8: %
B9: 1968 | C9: 1988 | D9: Change | E9: 1968 | F9: 1988 | G9: Change | H9: 1968 | I9: 1988 | J9: Change | K9: 1968 | L9: 1988 | M9: Change
A12: CENTER CITY | B12: 31.2 | C12: 30.5 | D12: =((C12-B12)/B12)*100 -> -2.2435897 | E12: 36.6 | F12: 28.9 | G12: =((F12-E12)/E12)*100 -> -21.038251 | H12: 45.3 | I12: 36 | J12: =((I12-H12)/H12)*100 -> -20.529801 | K12: 32.2 | L12: 30.5 | M12: =((L12-K12)/K12)*100 -> -5.2795031
A14: INNER SUBURBS | B14: 37.3 | C14: 35 | D14: =((C14-B14)/B14)*100 -> -6.1662198 | E14: 20.4 | F14: 22.8 | G14: =((F14-E14)/E14)*100 -> 11.764706 | H14: 27 | I14: 32.3 | J14: =((I14-H14)/H14)*100 -> 19.62963 | K14: 31.1 | L14: 30.4 | M14: =((L14-K14)/K14)*100 -> -2.2508039
A16: OUTER SUBURBS | B16: 45.2 | C16: 47.7 | D16: =((C16-B16)/B16)*100 -> 5.5309735 | E16: 29.4 | F16: 38.3 | G16: =((F16-E16)/E16)*100 -> 30.272109 | H16: 20.6 | I16: 25.6 | J16: =((I16-H16)/H16)*100 -> 24.271845 | K16: 33 | L16: 34.3 | M16: =((L16-K16)/K16)*100 -> 3.9393939
A19: Source: 1968 and 1987/88 Metropolitan Washington Council of Governments Household Travel Surveys
A20: A.M. Peak: 6-9 A.M.

Sheet D
A1: Table 3: | B1: Average Travel Time in minutes and Sample Size (N) for the Metropolitan
B2: Washington Region by Mode and Purpose (A.M. and P.M. Peak Period)
E6: P U R P O S E
A7: Mode | B7: Year | D7: Home to Work | E7: Work to | F7: Home to | G7: Other to | H7: Work to | I7: Other to | J7: Other to
D8: Work | E8: Home | F8: Other | G8: Home | H8: Other | I8: Work | J8: Other
A10: AUTO-1 | B10: 1968 | C10: Time | D10: 28.3 | E10: 32.5 | F10: 19.2 | G10: 17.8 | H10: 27.3 | I10: 24.4 | J10: 17.9
C11: N | D11: 11633 | E11: 9124 | F11: 3823 | G11: 3656 | H11: 996 | I11: 341 | J11: 738
B13: 1988 | C13: Time | D13: 28.9 | E13: 32.5 | F13: 18.6 | G13: 19.9 | H13: 26.6 | I13: 25.8 | J13: 17.8
C14: N | D14: 3260 | E14: 2181 | F14: 1378 | G14: 1456 | H14: 847 | I14: 734 | J14: 726
A16: AUTO-2 | B16: 1968 | C16: Time | D16: 32.3 | E16: 36.4 | F16: 17.2 | G16: 17.9 | H16: 27.8 | I16: 25.8 | J16: 17.1
C17: N | D17: 4962 | E17: 3792 | F17: 7068 | G17: 4191 | H17: 399 | I17: 178 | J17: 1337
B19: 1988 | C19: Time | D19: 31.2 | E19: 32.3 | F19: 18.1 | G19: 18.7 | H19: 26.4 | I19: 32.9 | J19: 17
C20: N | D20: 311 | E20: 196 | F20: 1025 | G20: 651 | H20: 180 | I20: 148 | J20: 530
A22: AUTO-3 | B22: 1968 | C22: Time | D22: 40.7 | E22: 47.3 | F22: 17.3 | G22: 18.5 | H22: 32.3 | I22: 35 | J22: 15.1
C23: N | D23: 403 | E23: 324 | F23: 1194 | G23: 745 | H23: 33 | I23: 27 | J23: 256
B25: 1988 | C25: Time | D25: 37.8 | E25: 44.1 | F25: 16.7 | G25: 15.1 | H25: 30.1 | I25: 33.5 | J25: 18.2
C26: N | D26: 105 | E26: 70 | F26: 601 | G26: 298 | H26: 57 | I26: 50 | J26: 233
A28: TRANSIT | B28: 1968 | C28: Time | D28: 44.3 | E28: 51.4 | F28: 39.6 | G28: 42.8 | H28: 38.5 | I28: 36.8 | J28: 33.5
C29: N | D29: 3176 | E29: 2693 | F29: 875 | G29: 391 | H29: 172 | I29: 44 | J29: 72
B31: 1988 | C31: Time | D31: 42.8 | E31: 46 | F31: 36 | G31: 36.3 | H31: 37.6 | I31: 27.2 | J31: 34.6
C32: N | D32: 991 | E32: 800 | F32: 174 | G32: 182 | H32: 159 | I32: 132 | J32: 87
A35: ALL | B35: 1968 | C35: Time | D35: =((D10*A!$D$130)+(D16*A!$D$136)+(D22*A!$D$142)+(D28*A!$D$148))/(A!$D$155) -> 32.050431 | E35: =((E10*A!$E$130)+(E16*A!$E$136)+(E22*A!$E$142)+(E28*A!$E$148))/(A!$E$155) -> 36.92363 | F35: =((F10*A!$F$130)+(F16*A!$F$136)+(F22*A!$F$142)+(F28*A!$F$148))/(A!$F$155) -> 19.311528 | G35: =((G10*A!$G$130)+(G16*A!$G$136)+(G22*A!$G$142)+(G28*A!$G$148))/(A!$G$155) -> 18.992875 | H35: =((H10*A!$H$130)+(H16*A!$H$136)+(H22*A!$H$142)+(H28*A!$H$148))/(A!$H$155) -> 28.731813 | I35: =((I10*A!$I$130)+(I16*A!$I$136)+(I22*A!$I$142)+(I28*A!$I$148))/(A!$I$155) -> 26.232203 | J35: =((J10*A!$J$130)+(J16*A!$J$136)+(J22*A!$J$142)+(J28*A!$J$148))/(A!$J$155) -> 17.624012
A36: MODES | C36: N | D36: =(D11+D17+D23+D29) -> 20174 | E36: =(E11+E17+E23+E29) -> 15933 | F36: =(F11+F17+F23+F29) -> 12960 | G36: =(G11+G17+G23+G29) -> 8983 | H36: =(H11+H17+H23+H29) -> 1600 | I36: =(I11+I17+I23+I29) -> 590 | J36: =(J11+J17+J23+J29) -> 2403
B38: 1988 | C38: Time | D38: =((D13*A!$D$133)+(D19*A!$D$139)+(D25*A!$D$145)+(D31*A!$D$151))/(A!$D$158) -> 32.205057 | E38: =((E13*A!$E$133)+(E19*A!$E$139)+(E25*A!$E$145)+(E31*A!$E$151))/(A!$E$158) -> 36.064152 | F38: =((F13*A!$F$133)+(F19*A!$F$139)+(F25*A!$F$145)+(F31*A!$F$151))/(A!$F$158) -> 19.032096 | G38: =((G13*A!$G$133)+(G19*A!$G$139)+(G25*A!$G$145)+(G31*A!$G$151))/(A!$G$158) -> 20.198879 | H38: =((H13*A!$H$133)+(H19*A!$H$139)+(H25*A!$H$145)+(H31*A!$H$151))/(A!$H$158) -> 28.138616 | I38: =((I13*A!$I$133)+(I19*A!$I$139)+(I25*A!$I$145)+(I31*A!$I$151))/(A!$I$158) -> 27.32312 | J38: =((J13*A!$J$133)+(J19*A!$J$139)+(J25*A!$J$145)+(J31*A!$J$151))/(A!$J$158) -> 18.517513
C39: N | D39: =(D14+D20+D26+D32) -> 4667 | E39: =(E14+E20+E26+E32) -> 3247 | F39: =(F14+F20+F26+F32) -> 3178 | G39: =(G14+G20+G26+G32) -> 2587 | H39: =(H14+H20+H26+H32) -> 1243 | I39: =(I14+I20+I26+I32) -> 1064 | J39: =(J14+J20+J26+J32) -> 1576
A42: Source: 1968 and 1987/88 Metropolitan Washington Council of Governments Household
A43: Travel Surveys.
A44: A.M. Peak: 6-9 A.M.; P.M. Peak: 3:30-6:30 P.M.

Sheet E
A1: Table 4: | B1: Difference of Means Test: Null Hypothesis: There Is No
B2: Difference In Travel Time Distributions By Mode And Purpose
B3: From 1968 To 1988.
F6: PURPOSE
B7: Home to | D7: Work to | F7: Home to | H7: Other to | J7: Work to | L7: Other to | N7: Other to
A8: MODE | B8: Work | D8: Home | F8: Other | H8: Home | J8: Other | L8: Work | N8: Other
A9: AUTO-1 | B9: 0.37133278 | C9: * | D9: 0 | E9: * | F9: 4.1563665 | H9: 8.8063641 | J9: 1.2376066 | K9: * | L9: 1.8224293 | M9: * | N9: 0.15831921 | O9: *
A11: AUTO-2 | B11: 0.507356 | C11: * | D11: 1.9658359 | F11: 2.40745 | H11: 1.138999 | I11: * | J11: 0.60730308 | K11: * | L11: 3.6691833 | N11: 0.088811142 | O11: *
A13: AUTO-3 | B13: 1.5014149 | C13: * | D13: 0.85338291 | E13: * | F13: 0.94483348 | G13: * | H13: 1.8598002 | I13: * | J13: 0.30618275 | K13: * | L13: 0.1134592 | M13: * | N13: 2.6239906
A15: TRANSIT | B15: 0.28587467 | C15: * | D15: 8.4540132 | F15: 1.9106426 | G15: * | H15: 4.2190141 | J15: 0.4463043 | K15: * | L15: 2.0913162 | N15: 0.19536713 | O15: *
A17: note: * indicates p s 0.05

Sheet F
A1: Table 5: Average Euclidean Travel Distance (in miles) for the Metropolitan Washington Region
A2: by Mode and Purpose (A.M. and P.M. Peak Period)
E5: P U R P O S E
A6: Mode | B6: Year | C6: Home to | D6: Work to | E6: Home to | F6: Other to | G6: Work to | H6: Other to | I6: Other to
C7: Work | D7: Home | E7: Other | F7: Home | G7: Other | H7: Work | I7: Other
A9: AUTO-1 | B9: 1968 | C9: 6.9 | D9: 6.9 | E9: 4.5 | F9: 4 | G9: 5.5 | H9: 5 | I9: 3.8
B11: 1988 | C11: 7.8 | D11: 8.3 | E11: 4.2 | F11: 4.5 | G11: 6.4 | H11: 6.3 | I11: 5
A13: AUTO-2 | B13: 1968 | C13: 6.8 | D13: 6.9 | E13: 3.9 | F13: 3.9 | G13: 5.3 | H13: 6 | I13: 3.5
B15: 1988 | C15: 8.6 | D15: 8 | E15: 4.2 | F15: 3.9 | G15: 5.7 | H15: 7.5 | I15: 4.4
A17: AUTO-3 | B17: 1968 | C17: 7.7 | D17: 9.8 | E17: 3.9 | F17: 3.9 | G17: 6 | H17: 5.7 | I17: 3.4
B19: 1988 | C19: 10.1 | D19: 11.5 | E19: 3.4 | F19: 3.8 | G19: 6.1 | H19: 13 | I19: 5.9
A21: TRANSIT | B21: 1968 | C21: 4.4 | D21: 4.5 | E21: 3.3 | F21: 3.4 | G21: 3.2 | H21: 5.1 | I21: 3.7
B23: 1988 | C23: 7.2 | D23: 7.5 | E23: 4 | F23: 4 | G23: 6.2 | H23: 4.6 | I23: 4.4
A26: ALL | B26: 1968 | C26: =((C9*A!$D$130)+(C13*A!$D$136)+(C17*A!$D$142)+(C21*A!$D$148))/(A!$D$155) -> 6.4978091 | D26: =((D9*A!$E$130)+(D13*A!$E$136)+(D17*A!$E$142)+(D21*A!$E$148))/(A!$E$155) -> 6.5533233 | E26: =((E9*A!$F$130)+(E13*A!$F$136)+(E17*A!$F$142)+(E21*A!$F$148))/(A!$F$155) -> 4.0364815 | F26: =((F9*A!$G$130)+(F13*A!$G$136)+(F17*A!$G$142)+(F21*A!$G$148))/(A!$G$155) -> 3.9189358 | G26: =((G9*A!$H$130)+(G13*A!$H$136)+(G17*A!$H$142)+(G21*A!$H$148))/(A!$H$155) -> 5.2131875 | H26: =((H9*A!$I$130)+(H13*A!$I$136)+(H17*A!$I$142)+(H21*A!$I$148))/(A!$I$155) -> 5.3411864 | I26: =((I9*A!$J$130)+(I13*A!$J$136)+(I17*A!$J$142)+(I21*A!$J$148))/(A!$J$155) -> 3.587474
A28: MODES | B28: 1988 | C28: =((C11*A!$D$133)+(C15*A!$D$139)+(C19*A!$D$145)+(C23*A!$D$151))/(A!$D$158) -> 7.7776516 | D28: =((D11*A!$E$133)+(D15*A!$E$139)+(D19*A!$E$145)+(D23*A!$E$151))/(A!$E$158) -> 8.1537727 | E28: =((E11*A!$F$133)+(E15*A!$F$139)+(E19*A!$F$145)+(E23*A!$F$151))/(A!$F$158) -> 4.0377596 | F28: =((F11*A!$G$133)+(F15*A!$G$139)+(F19*A!$G$145)+(F23*A!$G$151))/(A!$G$158) -> 4.2332045 | G28: =((G11*A!$H$133)+(G15*A!$H$139)+(G19*A!$H$145)+(G25*A!$H$151))/(A!$H$158) -> 5.4662108 | H28: =((H11*A!$I$133)+(H15*A!$I$139)+(H19*A!$I$145)+(H23*A!$I$151))/(A!$I$158) -> 6.5708647 | I28: =((I11*A!$J$133)+(I15*A!$J$139)+(I19*A!$J$145)+(I23*A!$J$151))/(A!$J$158) -> 4.8981599
A33: Source: 1968 and 1987/88 Metropolitan Washington Council of Governments Household Travel Surveys
A34: A.M. Peak: 6-9 A.M.; P.M. Peak: 3:30-6:30 P.M.

Sheet G
A1: Table 6: | B1: Percent Change in Speed Between 1968 and 1988 for the Metropolitan
B2: Washington Region, by Mode and Purpose (A.M. and P.M. Peak Period)
D6: P U R P O S E
A7: Mode | B7: Home to | C7: Work to | D7: Home to | E7: Other to | F7: Work to | G7: Other to | H7: Other to
B8: Work | C8: Home | D8: Other | E8: Home | F8: Other | G8: Work | H8: Other
A10: AUTO-1 | B10: 10.696555 | C10: 20.289855 | D10: -3.655914 | E10: 0.6281407 | F10: 19.425837 | G10: 19.162791 | H10: 32.318155
A12: AUTO-2 | B12: 30.929487 | C12: 30.659129 | D12: 2.3374416 | E12: -4.2780749 | F12: 13.250429 | G12: -1.9756839 | H12: 26.453782
A14: AUTO-3 | B14: 41.232048 | C14: 25.861909 | D14: -9.6883157 | E14: 19.375106 | F14: 9.0974529 | G14: 138.28227 | H14: 43.972204
A16: TRANSIT | B16: 69.371283 | C16: 86.231884 | D16: 33.333333 | E16: 38.713337 | F16: 98.387633 | G16: 22.029988 | H16: 15.13826
A18: ALL | B18: 19.121828 | C18: 27.387168 | D18: 1.5003442 | E18: 1.5697899 | F18: 7.0639633 | G18: 18.110705 | H18: 29.947018
A19: MODES
A21: Source: 1968 and 1987/88 MWCOG Household Travel Surveys
A22: A.M. Peak: 6-9 A.M.; P.M. Peak: 3:30-6:30 P.M.

Sheet H
A1: FIGURE 2: METROPOLITAN TRENDS

Sheet I
A1: FIGURE 1: WASHINGTON METROPOLITAN REGION
A3: FIGURE 2: METROPOLITAN TRENDS
A5: FIGURE 3: CUMULATIVE DISTRIBUTION OF TRAVEL TIMES: 1968 vs. 1988
A7: FIGURE 4: CUMULATIVE DISTRIBUTION OF TRAVEL TIMES BY MODE

Sheet Graph 1
